2020-07-03 18:48:44,628 ERROR: Exception on /user/w [GET] [in d:\udemy free\microblog github\microblog\venv\lib\site-packages\flask\app.py:1892]
Traceback (most recent call last):
  File "d:\udemy free\microblog github\microblog\venv\lib\site-packages\sqlalchemy\engine\base.py", line 1278, in _execute_context
    cursor, statement, parameters, context
  File "d:\udemy free\microblog github\microblog\venv\lib\site-packages\sqlalchemy\engine\default.py", line 593, in do_execute
    cursor.execute(statement, parameters)
sqlite3.OperationalError: no such table: followers

The above exception was the direct cause of the following exception:

Traceback (most recent call last):
  File "d:\udemy free\microblog github\microblog\venv\lib\site-packages\flask\app.py", line 2447, in wsgi_app
    response = self.full_dispatch_request()
  File "d:\udemy free\microblog github\microblog\venv\lib\site-packages\flask\app.py", line 1952, in full_dispatch_request
    rv = self.handle_user_exception(e)
  File "d:\udemy free\microblog github\microblog\venv\lib\site-packages\flask\app.py", line 1821, in handle_user_exception
    reraise(exc_type, exc_value, tb)
  File "d:\udemy free\microblog github\microblog\venv\lib\site-packages\flask\_compat.py", line 39, in reraise
    raise value
  File "d:\udemy free\microblog github\microblog\venv\lib\site-packages\flask\app.py", line 1950, in full_dispatch_request
    rv = self.dispatch_request()
  File "d:\udemy free\microblog github\microblog\venv\lib\site-packages\flask\app.py", line 1936, in dispatch_request
    return self.view_functions[rule.endpoint](**req.view_args)
  File "d:\udemy free\microblog github\microblog\venv\lib\site-packages\flask_login\utils.py", line 272, in decorated_view
    return func(*args, **kwargs)
  File "D:\udemy free\microblog github\microblog\app\routes.py", line 81, in user
    return render_template('user.html', user=user, posts=posts)
  File "d:\udemy free\microblog github\microblog\venv\lib\site-packages\flask\templating.py", line 140, in render_template
    ctx.app,
  File "d:\udemy free\microblog github\microblog\venv\lib\site-packages\flask\templating.py", line 120, in _render
    rv = template.render(context)
  File "d:\udemy free\microblog github\microblog\venv\lib\site-packages\jinja2\environment.py", line 1090, in render
    self.environment.handle_exception()
  File "d:\udemy free\microblog github\microblog\venv\lib\site-packages\jinja2\environment.py", line 832, in handle_exception
    reraise(*rewrite_traceback_stack(source=source))
  File "d:\udemy free\microblog github\microblog\venv\lib\site-packages\jinja2\_compat.py", line 28, in reraise
    raise value.with_traceback(tb)
  File "D:\udemy free\microblog github\microblog\app\templates\user.html", line 1, in top-level template code
    {% extends "base.html" %}
  File "D:\udemy free\microblog github\microblog\app\templates\base.html", line 30, in top-level template code
    {% block content %}{% endblock %}
  File "D:\udemy free\microblog github\microblog\app\templates\user.html", line 11, in block "content"
    <p>{{user.followers.count()}} followers, {{user.followed.count() }} following</p>
  File "d:\udemy free\microblog github\microblog\venv\lib\site-packages\sqlalchemy\orm\dynamic.py", line 335, in count
    return self._clone(sess).count()
  File "d:\udemy free\microblog github\microblog\venv\lib\site-packages\sqlalchemy\orm\query.py", line 3771, in count
    return self.from_self(col).scalar()
  File "d:\udemy free\microblog github\microblog\venv\lib\site-packages\sqlalchemy\orm\query.py", line 3491, in scalar
    ret = self.one()
  File "d:\udemy free\microblog github\microblog\venv\lib\site-packages\sqlalchemy\orm\query.py", line 3458, in one
    ret = self.one_or_none()
  File "d:\udemy free\microblog github\microblog\venv\lib\site-packages\sqlalchemy\orm\query.py", line 3427, in one_or_none
    ret = list(self)
  File "d:\udemy free\microblog github\microblog\venv\lib\site-packages\sqlalchemy\orm\query.py", line 3503, in __iter__
    return self._execute_and_instances(context)
  File "d:\udemy free\microblog github\microblog\venv\lib\site-packages\sqlalchemy\orm\query.py", line 3528, in _execute_and_instances
    result = conn.execute(querycontext.statement, self._params)
  File "d:\udemy free\microblog github\microblog\venv\lib\site-packages\sqlalchemy\engine\base.py", line 1014, in execute
    return meth(self, multiparams, params)
  File "d:\udemy free\microblog github\microblog\venv\lib\site-packages\sqlalchemy\sql\elements.py", line 298, in _execute_on_connection
    return connection._execute_clauseelement(self, multiparams, params)
  File "d:\udemy free\microblog github\microblog\venv\lib\site-packages\sqlalchemy\engine\base.py", line 1133, in _execute_clauseelement
    distilled_params,
  File "d:\udemy free\microblog github\microblog\venv\lib\site-packages\sqlalchemy\engine\base.py", line 1318, in _execute_context
    e, statement, parameters, cursor, context
  File "d:\udemy free\microblog github\microblog\venv\lib\site-packages\sqlalchemy\engine\base.py", line 1512, in _handle_dbapi_exception
    sqlalchemy_exception, with_traceback=exc_info[2], from_=e
  File "d:\udemy free\microblog github\microblog\venv\lib\site-packages\sqlalchemy\util\compat.py", line 178, in raise_
    raise exception
  File "d:\udemy free\microblog github\microblog\venv\lib\site-packages\sqlalchemy\engine\base.py", line 1278, in _execute_context
    cursor, statement, parameters, context
  File "d:\udemy free\microblog github\microblog\venv\lib\site-packages\sqlalchemy\engine\default.py", line 593, in do_execute
    cursor.execute(statement, parameters)
sqlalchemy.exc.OperationalError: (sqlite3.OperationalError) no such table: followers
[SQL: SELECT count(*) AS count_1 
FROM (SELECT user.id AS user_id, user.username AS user_username, user.email AS user_email, user.password_hash AS user_password_hash, user.about_me AS user_about_me, user.last_seen AS user_last_seen 
FROM user, followers 
WHERE followers.followed_id = ? AND followers.follower_id = user.id) AS anon_1]
[parameters: (5,)]
(Background on this error at: http://sqlalche.me/e/13/e3q8)
2020-07-03 18:53:59,394 INFO: Microblog startup [in D:\udemy free\microblog github\microblog\app\__init__.py:43]
2020-07-03 18:54:08,974 INFO: Microblog startup [in D:\udemy free\microblog github\microblog\app\__init__.py:43]
2020-07-03 18:56:55,712 INFO: Microblog startup [in D:\udemy free\microblog github\microblog\app\__init__.py:43]
2020-07-03 18:57:28,301 INFO: Microblog startup [in D:\udemy free\microblog github\microblog\app\__init__.py:43]
2020-07-03 18:57:35,982 INFO: Microblog startup [in D:\udemy free\microblog github\microblog\app\__init__.py:43]
2020-07-03 18:57:57,654 INFO: Microblog startup [in D:\udemy free\microblog github\microblog\app\__init__.py:43]
2020-07-03 18:58:05,760 INFO: Microblog startup [in D:\udemy free\microblog github\microblog\app\__init__.py:43]
2020-07-03 18:58:12,963 INFO: Microblog startup [in D:\udemy free\microblog github\microblog\app\__init__.py:43]
2020-07-03 18:58:23,073 INFO: Microblog startup [in D:\udemy free\microblog github\microblog\app\__init__.py:43]
2020-07-03 19:05:09,153 INFO: Microblog startup [in D:\udemy free\microblog github\microblog\app\__init__.py:43]
2020-07-03 19:06:08,467 INFO: Microblog startup [in D:\udemy free\microblog github\microblog\app\__init__.py:43]
2020-07-03 19:06:42,851 INFO: Microblog startup [in D:\udemy free\microblog github\microblog\app\__init__.py:43]
2020-07-03 19:08:28,436 INFO: Microblog startup [in D:\udemy free\microblog github\microblog\app\__init__.py:43]
2020-07-03 19:08:34,512 ERROR: Exception on / [POST] [in d:\udemy free\microblog github\microblog\venv\lib\site-packages\flask\app.py:1892]
Traceback (most recent call last):
  File "d:\udemy free\microblog github\microblog\venv\lib\site-packages\flask\app.py", line 2447, in wsgi_app
    response = self.full_dispatch_request()
  File "d:\udemy free\microblog github\microblog\venv\lib\site-packages\flask\app.py", line 1952, in full_dispatch_request
    rv = self.handle_user_exception(e)
  File "d:\udemy free\microblog github\microblog\venv\lib\site-packages\flask\app.py", line 1821, in handle_user_exception
    reraise(exc_type, exc_value, tb)
  File "d:\udemy free\microblog github\microblog\venv\lib\site-packages\flask\_compat.py", line 39, in reraise
    raise value
  File "d:\udemy free\microblog github\microblog\venv\lib\site-packages\flask\app.py", line 1950, in full_dispatch_request
    rv = self.dispatch_request()
  File "d:\udemy free\microblog github\microblog\venv\lib\site-packages\flask\app.py", line 1936, in dispatch_request
    return self.view_functions[rule.endpoint](**req.view_args)
  File "d:\udemy free\microblog github\microblog\venv\lib\site-packages\flask_login\utils.py", line 272, in decorated_view
    return func(*args, **kwargs)
  File "D:\udemy free\microblog github\microblog\app\routes.py", line 23, in index
    post = Post(body=form.post.data, author=current_user)
NameError: name 'Post' is not defined
2020-07-03 19:10:30,551 INFO: Microblog startup [in D:\udemy free\microblog github\microblog\app\__init__.py:43]
2020-07-03 19:21:57,583 INFO: Microblog startup [in D:\udemy free\microblog github\microblog\app\__init__.py:43]
2020-07-03 19:23:17,815 INFO: Microblog startup [in D:\udemy free\microblog github\microblog\app\__init__.py:43]
2020-07-03 19:27:53,978 INFO: Microblog startup [in D:\udemy free\microblog github\microblog\app\__init__.py:43]
